Adding propositions to chunks: 100%|██████████| 43/43 [01:16<00:00,  1.77s/proposition]
Processing chunks: 100%|██████████| 43/43 [34:56<00:00, 48.76s/chunk]
God blessed us all!
Processing 3th book(s): Cell_Biology_Alberts.txt
gid: fedKjUdbdezrmujgqt5iE4
Adding propositions to chunks: 100%|██████████| 154/154 [05:02<00:00,  1.97s/proposition]
Processing chunks: 100%|██████████| 154/154 [2:13:18<00:00, 51.94s/chunk] 
God blessed us all!
Processing 4th book(s): First_Aid_Step1.txt
gid: 4dWPVub2XhYoCMbXJ38LNj
Adding propositions to chunks: 100%|██████████| 21/21 [00:51<00:00,  2.43s/proposition]
Processing chunks: 100%|██████████| 21/21 [29:55<00:00, 85.49s/chunk] 
God blessed us all!
Processing 5th book(s): First_Aid_Step2.txt
gid: EV7NPeqRrTMwKjMqtZ7TWN
Adding propositions to chunks: 100%|██████████| 33/33 [01:13<00:00,  2.24s/proposition]
Processing chunks: 100%|██████████| 33/33 [45:01<00:00, 81.87s/chunk] 
God blessed us all!
Processing 6th book(s): Gynecology_Novak.txt
gid: W2NsyBSdk9mtkpX9B7eEaA
Adding propositions to chunks: 100%|██████████| 178/178 [06:17<00:00,  2.12s/proposition]
Processing chunks:  48%|████▊     | 86/178 [1:58:10<1:50:10, 71.85s/chunk] 2025-05-22 01:01:18,199 - camel.models.model_manager - ERROR - Error processing with model: <camel.models.openai_model.OpenAIModel object at 0x72e6698887d0>
2025-05-22 01:01:18,199 - camel.agents.chat_agent - ERROR - An error occurred while running model gpt-4o-mini, index: 0
Traceback (most recent call last):
  File "/home/ngjabach/Documents/NgJaBach/Medical-Graph-RAG/.venv/lib/python3.12/site-packages/httpx/_transports/default.py", line 72, in map_httpcore_exceptions
    yield
  File "/home/ngjabach/Documents/NgJaBach/Medical-Graph-RAG/.venv/lib/python3.12/site-packages/httpx/_transports/default.py", line 236, in handle_request
    resp = self._pool.handle_request(req)
           ^^^^^^^^^^^^^^^^^^^^^^^^^^^^^^
  File "/home/ngjabach/Documents/NgJaBach/Medical-Graph-RAG/.venv/lib/python3.12/site-packages/httpcore/_sync/connection_pool.py", line 256, in handle_request
    raise exc from None
  File "/home/ngjabach/Documents/NgJaBach/Medical-Graph-RAG/.venv/lib/python3.12/site-packages/httpcore/_sync/connection_pool.py", line 236, in handle_request
    response = connection.handle_request(
               ^^^^^^^^^^^^^^^^^^^^^^^^^^
  File "/home/ngjabach/Documents/NgJaBach/Medical-Graph-RAG/.venv/lib/python3.12/site-packages/httpcore/_sync/connection.py", line 103, in handle_request
    return self._connection.handle_request(request)
           ^^^^^^^^^^^^^^^^^^^^^^^^^^^^^^^^^^^^^^^^
  File "/home/ngjabach/Documents/NgJaBach/Medical-Graph-RAG/.venv/lib/python3.12/site-packages/httpcore/_sync/http11.py", line 136, in handle_request
    raise exc
  File "/home/ngjabach/Documents/NgJaBach/Medical-Graph-RAG/.venv/lib/python3.12/site-packages/httpcore/_sync/http11.py", line 106, in handle_request
    ) = self._receive_response_headers(**kwargs)
        ^^^^^^^^^^^^^^^^^^^^^^^^^^^^^^^^^^^^^^^^
  File "/home/ngjabach/Documents/NgJaBach/Medical-Graph-RAG/.venv/lib/python3.12/site-packages/httpcore/_sync/http11.py", line 177, in _receive_response_headers
    event = self._receive_event(timeout=timeout)
            ^^^^^^^^^^^^^^^^^^^^^^^^^^^^^^^^^^^^
  File "/home/ngjabach/Documents/NgJaBach/Medical-Graph-RAG/.venv/lib/python3.12/site-packages/httpcore/_sync/http11.py", line 217, in _receive_event
    data = self._network_stream.read(
           ^^^^^^^^^^^^^^^^^^^^^^^^^^
  File "/home/ngjabach/Documents/NgJaBach/Medical-Graph-RAG/.venv/lib/python3.12/site-packages/httpcore/_backends/sync.py", line 126, in read
    with map_exceptions(exc_map):
  File "/usr/lib/python3.12/contextlib.py", line 158, in __exit__
    self.gen.throw(value)
  File "/home/ngjabach/Documents/NgJaBach/Medical-Graph-RAG/.venv/lib/python3.12/site-packages/httpcore/_exceptions.py", line 14, in map_exceptions
    raise to_exc(exc) from exc
httpcore.ReadTimeout: The read operation timed out

The above exception was the direct cause of the following exception:

Traceback (most recent call last):
  File "/home/ngjabach/Documents/NgJaBach/Medical-Graph-RAG/.venv/lib/python3.12/site-packages/openai/_base_client.py", line 989, in _request
    response = self._client.send(
               ^^^^^^^^^^^^^^^^^^
  File "/home/ngjabach/Documents/NgJaBach/Medical-Graph-RAG/.venv/lib/python3.12/site-packages/httpx/_client.py", line 926, in send
    response = self._send_handling_auth(
               ^^^^^^^^^^^^^^^^^^^^^^^^^
  File "/home/ngjabach/Documents/NgJaBach/Medical-Graph-RAG/.venv/lib/python3.12/site-packages/httpx/_client.py", line 954, in _send_handling_auth
    response = self._send_handling_redirects(
               ^^^^^^^^^^^^^^^^^^^^^^^^^^^^^^
  File "/home/ngjabach/Documents/NgJaBach/Medical-Graph-RAG/.venv/lib/python3.12/site-packages/httpx/_client.py", line 991, in _send_handling_redirects
    response = self._send_single_request(request)
               ^^^^^^^^^^^^^^^^^^^^^^^^^^^^^^^^^^
  File "/home/ngjabach/Documents/NgJaBach/Medical-Graph-RAG/.venv/lib/python3.12/site-packages/httpx/_client.py", line 1027, in _send_single_request
    response = transport.handle_request(request)
               ^^^^^^^^^^^^^^^^^^^^^^^^^^^^^^^^^
  File "/home/ngjabach/Documents/NgJaBach/Medical-Graph-RAG/.venv/lib/python3.12/site-packages/httpx/_transports/default.py", line 235, in handle_request
    with map_httpcore_exceptions():
  File "/usr/lib/python3.12/contextlib.py", line 158, in __exit__
    self.gen.throw(value)
  File "/home/ngjabach/Documents/NgJaBach/Medical-Graph-RAG/.venv/lib/python3.12/site-packages/httpx/_transports/default.py", line 89, in map_httpcore_exceptions
    raise mapped_exc(message) from exc
httpx.ReadTimeout: The read operation timed out

The above exception was the direct cause of the following exception:

Traceback (most recent call last):
  File "/home/ngjabach/Documents/NgJaBach/Medical-Graph-RAG/.venv/lib/python3.12/site-packages/camel/agents/chat_agent.py", line 1088, in _step_model_response
    response = self.model_backend.run(openai_messages)
               ^^^^^^^^^^^^^^^^^^^^^^^^^^^^^^^^^^^^^^^
  File "/home/ngjabach/Documents/NgJaBach/Medical-Graph-RAG/.venv/lib/python3.12/site-packages/camel/models/model_manager.py", line 211, in run
    raise exc
  File "/home/ngjabach/Documents/NgJaBach/Medical-Graph-RAG/.venv/lib/python3.12/site-packages/camel/models/model_manager.py", line 201, in run
    response = self.current_model.run(messages)
               ^^^^^^^^^^^^^^^^^^^^^^^^^^^^^^^^
  File "/home/ngjabach/Documents/NgJaBach/Medical-Graph-RAG/.venv/lib/python3.12/site-packages/camel/models/openai_model.py", line 159, in run
    response = self._client.chat.completions.create(
               ^^^^^^^^^^^^^^^^^^^^^^^^^^^^^^^^^^^^^
  File "/home/ngjabach/Documents/NgJaBach/Medical-Graph-RAG/.venv/lib/python3.12/site-packages/openai/_utils/_utils.py", line 279, in wrapper
    return func(*args, **kwargs)
           ^^^^^^^^^^^^^^^^^^^^^
  File "/home/ngjabach/Documents/NgJaBach/Medical-Graph-RAG/.venv/lib/python3.12/site-packages/openai/resources/chat/completions/completions.py", line 929, in create
    return self._post(
           ^^^^^^^^^^^
  File "/home/ngjabach/Documents/NgJaBach/Medical-Graph-RAG/.venv/lib/python3.12/site-packages/openai/_base_client.py", line 1276, in post
    return cast(ResponseT, self.request(cast_to, opts, stream=stream, stream_cls=stream_cls))
                           ^^^^^^^^^^^^^^^^^^^^^^^^^^^^^^^^^^^^^^^^^^^^^^^^^^^^^^^^^^^^^^^^^
  File "/home/ngjabach/Documents/NgJaBach/Medical-Graph-RAG/.venv/lib/python3.12/site-packages/openai/_base_client.py", line 949, in request
    return self._request(
           ^^^^^^^^^^^^^^
  File "/home/ngjabach/Documents/NgJaBach/Medical-Graph-RAG/.venv/lib/python3.12/site-packages/openai/_base_client.py", line 998, in _request
    return self._retry_request(
           ^^^^^^^^^^^^^^^^^^^^
  File "/home/ngjabach/Documents/NgJaBach/Medical-Graph-RAG/.venv/lib/python3.12/site-packages/openai/_base_client.py", line 1091, in _retry_request
    return self._request(
           ^^^^^^^^^^^^^^
  File "/home/ngjabach/Documents/NgJaBach/Medical-Graph-RAG/.venv/lib/python3.12/site-packages/openai/_base_client.py", line 998, in _request
    return self._retry_request(
           ^^^^^^^^^^^^^^^^^^^^
  File "/home/ngjabach/Documents/NgJaBach/Medical-Graph-RAG/.venv/lib/python3.12/site-packages/openai/_base_client.py", line 1091, in _retry_request
    return self._request(
           ^^^^^^^^^^^^^^
  File "/home/ngjabach/Documents/NgJaBach/Medical-Graph-RAG/.venv/lib/python3.12/site-packages/openai/_base_client.py", line 998, in _request
    return self._retry_request(
           ^^^^^^^^^^^^^^^^^^^^
  File "/home/ngjabach/Documents/NgJaBach/Medical-Graph-RAG/.venv/lib/python3.12/site-packages/openai/_base_client.py", line 1091, in _retry_request
    return self._request(
           ^^^^^^^^^^^^^^
  File "/home/ngjabach/Documents/NgJaBach/Medical-Graph-RAG/.venv/lib/python3.12/site-packages/openai/_base_client.py", line 1008, in _request
    raise APITimeoutError(request=request) from err
openai.APITimeoutError: Request timed out.
Processing chunks:  48%|████▊     | 86/178 [2:10:14<2:19:20, 90.87s/chunk]